Traceback (most recent call last):
  File "C:\Users\CoolG\OneDrive\Desktop\Gautam\Year 3\UCSC\Data files\M33 Data\M33\venv2\Lib\site-packages\numpy\_core\records.py", line 427, in __getattribute__
    res = fielddict[attr][:2]
          ~~~~~~~~~^^^^^^
KeyError: 'newbyteorder'

The above exception was the direct cause of the following exception:

Traceback (most recent call last):
  File "C:\Users\CoolG\OneDrive\Desktop\Gautam\Year 3\UCSC\Data files\M33 Data\M33\Codes\print_fits_columns.py", line 9, in <module>
    df = pd.DataFrame(data.byteswap().newbyteorder())
                      ^^^^^^^^^^^^^^^^^^^^^^^^^^^^
  File "C:\Users\CoolG\OneDrive\Desktop\Gautam\Year 3\UCSC\Data files\M33 Data\M33\venv2\Lib\site-packages\astropy\io\fits\fitsrec.py", line 524, in __getattribute__
    return super().__getattribute__(attr)
           ^^^^^^^^^^^^^^^^^^^^^^^^^^^^^^
  File "C:\Users\CoolG\OneDrive\Desktop\Gautam\Year 3\UCSC\Data files\M33 Data\M33\venv2\Lib\site-packages\numpy\_core\records.py", line 429, in __getattribute__
    raise AttributeError(f"recarray has no attribute {attr}") from e
AttributeError: recarray has no attribute newbyteorder
